[2024-07-07T14:16:24.894+0000] {local_task_job_runner.py:120} INFO - ::group::Pre task execution logs
[2024-07-07T14:16:24.931+0000] {taskinstance.py:2076} INFO - Dependencies all met for dep_context=non-requeueable deps ti=<TaskInstance: clickhouse_etl_dag.edw_load manual__2024-07-07T14:15:47.553379+00:00 [queued]>
[2024-07-07T14:16:24.947+0000] {taskinstance.py:2076} INFO - Dependencies all met for dep_context=requeueable deps ti=<TaskInstance: clickhouse_etl_dag.edw_load manual__2024-07-07T14:15:47.553379+00:00 [queued]>
[2024-07-07T14:16:24.949+0000] {taskinstance.py:2306} INFO - Starting attempt 1 of 0
[2024-07-07T14:16:24.975+0000] {taskinstance.py:2330} INFO - Executing <Task(PythonOperator): edw_load> on 2024-07-07 14:15:47.553379+00:00
[2024-07-07T14:16:24.983+0000] {warnings.py:112} WARNING - /home/***/.local/lib/python3.12/site-packages/***/task/task_runner/standard_task_runner.py:61: DeprecationWarning: This process (pid=244) is multi-threaded, use of fork() may lead to deadlocks in the child.
  pid = os.fork()

[2024-07-07T14:16:24.985+0000] {standard_task_runner.py:63} INFO - Started process 246 to run task
[2024-07-07T14:16:24.985+0000] {standard_task_runner.py:90} INFO - Running: ['***', 'tasks', 'run', 'clickhouse_etl_dag', 'edw_load', 'manual__2024-07-07T14:15:47.553379+00:00', '--job-id', '33', '--raw', '--subdir', 'DAGS_FOLDER/clickhouse.py', '--cfg-path', '/tmp/tmplakvuwun']
[2024-07-07T14:16:24.987+0000] {standard_task_runner.py:91} INFO - Job 33: Subtask edw_load
[2024-07-07T14:16:25.060+0000] {task_command.py:426} INFO - Running <TaskInstance: clickhouse_etl_dag.edw_load manual__2024-07-07T14:15:47.553379+00:00 [running]> on host dfb367ef2d3b
[2024-07-07T14:16:25.209+0000] {taskinstance.py:2648} INFO - Exporting env vars: AIRFLOW_CTX_DAG_EMAIL='franklinnwosu008@gmail.com' AIRFLOW_CTX_DAG_OWNER='Ifeanyi_DArTech_Org' AIRFLOW_CTX_DAG_ID='clickhouse_etl_dag' AIRFLOW_CTX_TASK_ID='edw_load' AIRFLOW_CTX_EXECUTION_DATE='2024-07-07T14:15:47.553379+00:00' AIRFLOW_CTX_TRY_NUMBER='1' AIRFLOW_CTX_DAG_RUN_ID='manual__2024-07-07T14:15:47.553379+00:00'
[2024-07-07T14:16:25.213+0000] {taskinstance.py:430} INFO - ::endgroup::
[2024-07-07T14:16:25.234+0000] {connection.py:399} INFO - Snowflake Connector for Python Version: 3.10.1, Python Version: 3.12.4, Platform: Linux-5.15.153.1-microsoft-standard-WSL2-x86_64-with-glibc2.36
[2024-07-07T14:16:25.236+0000] {connection.py:1239} INFO - This connection is in OCSP Fail Open Mode. TLS Certificates would be checked for validity and revocation status. Any other Certificate Revocation related exceptions or OCSP Responder failures would be disregarded in favor of connectivity.
[2024-07-07T14:16:25.976+0000] {cursor.py:1149} INFO - Number of results in first chunk: 1
[2024-07-07T14:16:26.039+0000] {cursor.py:1149} INFO - Number of results in first chunk: 1
[2024-07-07T14:16:26.579+0000] {taskinstance.py:441} INFO - ::group::Post task execution logs
[2024-07-07T14:16:26.580+0000] {taskinstance.py:2905} ERROR - Task failed with exception
Traceback (most recent call last):
  File "/home/airflow/.local/lib/python3.12/site-packages/sqlalchemy/engine/base.py", line 1910, in _execute_context
    self.dialect.do_execute(
  File "/home/airflow/.local/lib/python3.12/site-packages/sqlalchemy/engine/default.py", line 736, in do_execute
    cursor.execute(statement, parameters)
  File "/home/airflow/.local/lib/python3.12/site-packages/snowflake/connector/cursor.py", line 1080, in execute
    Error.errorhandler_wrapper(self.connection, self, error_class, errvalue)
  File "/home/airflow/.local/lib/python3.12/site-packages/snowflake/connector/errors.py", line 290, in errorhandler_wrapper
    handed_over = Error.hand_to_other_handler(
                  ^^^^^^^^^^^^^^^^^^^^^^^^^^^^
  File "/home/airflow/.local/lib/python3.12/site-packages/snowflake/connector/errors.py", line 345, in hand_to_other_handler
    cursor.errorhandler(connection, cursor, error_class, error_value)
  File "/home/airflow/.local/lib/python3.12/site-packages/snowflake/connector/errors.py", line 221, in default_errorhandler
    raise error_class(
snowflake.connector.errors.ProgrammingError: 000904 (42000): 01b582b8-0000-5354-0000-0000d3314105: Uncaught exception of type 'STATEMENT_ERROR' on line 47 at position 8 : SQL compilation error: error line 1 at position 32
invalid identifier 'RUN_TIME'

The above exception was the direct cause of the following exception:

Traceback (most recent call last):
  File "/home/airflow/.local/lib/python3.12/site-packages/airflow/models/taskinstance.py", line 465, in _execute_task
    result = _execute_callable(context=context, **execute_callable_kwargs)
             ^^^^^^^^^^^^^^^^^^^^^^^^^^^^^^^^^^^^^^^^^^^^^^^^^^^^^^^^^^^^^
  File "/home/airflow/.local/lib/python3.12/site-packages/airflow/models/taskinstance.py", line 432, in _execute_callable
    return execute_callable(context=context, **execute_callable_kwargs)
           ^^^^^^^^^^^^^^^^^^^^^^^^^^^^^^^^^^^^^^^^^^^^^^^^^^^^^^^^^^^^
  File "/home/airflow/.local/lib/python3.12/site-packages/airflow/models/baseoperator.py", line 401, in wrapper
    return func(self, *args, **kwargs)
           ^^^^^^^^^^^^^^^^^^^^^^^^^^^
  File "/home/airflow/.local/lib/python3.12/site-packages/airflow/operators/python.py", line 235, in execute
    return_value = self.execute_callable()
                   ^^^^^^^^^^^^^^^^^^^^^^^
  File "/home/airflow/.local/lib/python3.12/site-packages/airflow/operators/python.py", line 252, in execute_callable
    return self.python_callable(*self.op_args, **self.op_kwargs)
           ^^^^^^^^^^^^^^^^^^^^^^^^^^^^^^^^^^^^^^^^^^^^^^^^^^^^^
  File "/opt/airflow/dags/modules/load.py", line 28, in exec_procedure
    session.execute('call "STG".agg_trip_data()')
  File "/home/airflow/.local/lib/python3.12/site-packages/sqlalchemy/orm/session.py", line 1717, in execute
    result = conn._execute_20(statement, params or {}, execution_options)
             ^^^^^^^^^^^^^^^^^^^^^^^^^^^^^^^^^^^^^^^^^^^^^^^^^^^^^^^^^^^^
  File "/home/airflow/.local/lib/python3.12/site-packages/sqlalchemy/engine/base.py", line 1710, in _execute_20
    return meth(self, args_10style, kwargs_10style, execution_options)
           ^^^^^^^^^^^^^^^^^^^^^^^^^^^^^^^^^^^^^^^^^^^^^^^^^^^^^^^^^^^
  File "/home/airflow/.local/lib/python3.12/site-packages/sqlalchemy/sql/elements.py", line 334, in _execute_on_connection
    return connection._execute_clauseelement(
           ^^^^^^^^^^^^^^^^^^^^^^^^^^^^^^^^^^
  File "/home/airflow/.local/lib/python3.12/site-packages/sqlalchemy/engine/base.py", line 1577, in _execute_clauseelement
    ret = self._execute_context(
          ^^^^^^^^^^^^^^^^^^^^^^
  File "/home/airflow/.local/lib/python3.12/site-packages/sqlalchemy/engine/base.py", line 1953, in _execute_context
    self._handle_dbapi_exception(
  File "/home/airflow/.local/lib/python3.12/site-packages/sqlalchemy/engine/base.py", line 2134, in _handle_dbapi_exception
    util.raise_(
  File "/home/airflow/.local/lib/python3.12/site-packages/sqlalchemy/util/compat.py", line 211, in raise_
    raise exception
  File "/home/airflow/.local/lib/python3.12/site-packages/sqlalchemy/engine/base.py", line 1910, in _execute_context
    self.dialect.do_execute(
  File "/home/airflow/.local/lib/python3.12/site-packages/sqlalchemy/engine/default.py", line 736, in do_execute
    cursor.execute(statement, parameters)
  File "/home/airflow/.local/lib/python3.12/site-packages/snowflake/connector/cursor.py", line 1080, in execute
    Error.errorhandler_wrapper(self.connection, self, error_class, errvalue)
  File "/home/airflow/.local/lib/python3.12/site-packages/snowflake/connector/errors.py", line 290, in errorhandler_wrapper
    handed_over = Error.hand_to_other_handler(
                  ^^^^^^^^^^^^^^^^^^^^^^^^^^^^
  File "/home/airflow/.local/lib/python3.12/site-packages/snowflake/connector/errors.py", line 345, in hand_to_other_handler
    cursor.errorhandler(connection, cursor, error_class, error_value)
  File "/home/airflow/.local/lib/python3.12/site-packages/snowflake/connector/errors.py", line 221, in default_errorhandler
    raise error_class(
sqlalchemy.exc.ProgrammingError: (snowflake.connector.errors.ProgrammingError) 000904 (42000): 01b582b8-0000-5354-0000-0000d3314105: Uncaught exception of type 'STATEMENT_ERROR' on line 47 at position 8 : SQL compilation error: error line 1 at position 32
invalid identifier 'RUN_TIME'
[SQL: call "STG".agg_trip_data()]
(Background on this error at: https://sqlalche.me/e/14/f405)
[2024-07-07T14:16:26.602+0000] {taskinstance.py:1206} INFO - Marking task as FAILED. dag_id=clickhouse_etl_dag, task_id=edw_load, run_id=manual__2024-07-07T14:15:47.553379+00:00, execution_date=20240707T141547, start_date=20240707T141624, end_date=20240707T141626
[2024-07-07T14:16:26.630+0000] {standard_task_runner.py:110} ERROR - Failed to execute job 33 for task edw_load ((snowflake.connector.errors.ProgrammingError) 000904 (42000): 01b582b8-0000-5354-0000-0000d3314105: Uncaught exception of type 'STATEMENT_ERROR' on line 47 at position 8 : SQL compilation error: error line 1 at position 32
invalid identifier 'RUN_TIME'
[SQL: call "STG".agg_trip_data()]
(Background on this error at: https://sqlalche.me/e/14/f405); 246)
[2024-07-07T14:16:26.648+0000] {local_task_job_runner.py:240} INFO - Task exited with return code 1
[2024-07-07T14:16:26.669+0000] {local_task_job_runner.py:222} INFO - ::endgroup::
